<?xml version="1.0" ?>
<!-- =================================================================================== -->
<!-- |    This document was autogenerated by xacro from /home/albert/umov_ws/src/description/urdf/arduinobot.urdf.xacro | -->
<!-- |    EDITING THIS FILE BY HAND IS NOT RECOMMENDED                                 | -->
<!-- =================================================================================== -->
<robot name="arduinobot">
  <!-- Gazebo ros2_control plugin -->
  <gazebo>
    <plugin filename="libgazebo_ros2_control.so" name="gazebo_ros2_control">
      <robot_param>robot_description</robot_param>
      <robot_param_node>robot_state_publisher</robot_param_node>
      <parameters>/home/albert/umov_ws/install/arduinobot_controller/share/arduinobot_controller/config/arduinobot_controllers.yaml</parameters>
    </plugin>
  </gazebo>
  <gazebo reference="base_link">
    <material>Gazebo/Blue</material>
  </gazebo>
  <gazebo reference="base_plate">
    <material>Gazebo/Red</material>
  </gazebo>
  <gazebo reference="claw_support">
    <material>Gazebo/ZincYellow</material>
  </gazebo>
  <gazebo reference="forward_drive_arm">
    <material>Gazebo/Purple</material>
  </gazebo>
  <gazebo reference="horizontal_arm">
    <material>Gazebo/Turquoise</material>
  </gazebo>
  <gazebo reference="gripper_right">
    <material>Gazebo/Orange</material>
  </gazebo>
  <gazebo reference="gripper_left">
    <material>Gazebo/Orange</material>
  </gazebo>
  <ros2_control name="RobotSystem" type="system">
    <!-- ros2_control Gazebo -->
    <hardware>
      <plugin>gazebo_ros2_control/GazeboSystem</plugin>
    </hardware>
    <joint name="joint_1">
      <command_interface name="position">
        <param name="min">-1.570796326795</param>
        <param name="max">1.570796326795</param>
      </command_interface>
      <state_interface name="position"/>
    </joint>
    <joint name="joint_2">
      <command_interface name="position">
        <param name="min">-1.570796326795</param>
        <param name="max">1.570796326795</param>
      </command_interface>
      <state_interface name="position"/>
    </joint>
    <joint name="joint_3">
      <command_interface name="position">
        <param name="min">-1.570796326795</param>
        <param name="max">1.570796326795</param>
      </command_interface>
      <state_interface name="position"/>
    </joint>
    <joint name="joint_4">
      <command_interface name="position">
        <param name="min">-1.570796326795</param>
        <param name="max">1.570796326795</param>
      </command_interface>
      <state_interface name="position"/>
    </joint>
    <joint name="joint_5">
      <command_interface name="position">
        <param name="min">-1.570796326795</param>
        <param name="max">0</param>
      </command_interface>
      <state_interface name="position"/>
    </joint>
    <joint name="joint_6">
      <param name="mimic">joint_5</param>
      <param name="multiplier">-1</param>
      <command_interface name="position">
        <param name="min">0.0</param>
        <param name="max">1.570796326795</param>
      </command_interface>
    </joint>
  </ros2_control>
  <material name="green">
    <color rgba="0 0.75 0 1"/>
  </material>
  <material name="blue">
    <color rgba="0 0 0.75 1"/>
  </material>
  <material name="grey">
    <color rgba="0.5 0.5 0.5 1"/>
  </material>
  <material name="yellow">
    <color rgba="1.0 0.93 0.7 1"/>
  </material>
  <material name="purple">
    <color rgba="0.4 0.23 0.72 1"/>
  </material>
  <material name="turquoise">
    <color rgba="0.05 0.737 0.690 1.0"/>
  </material>
  <material name="skyblue">
    <color rgba="0.2 1.0 1.0"/>
  </material>
  <material name="orange">
    <color rgba="1.0 0.2 0.2 1.0"/>
  </material>
  <material name="pink">
    <color rgba="1.0 0 1.0 1.0"/>
  </material>
  <material name="red">
    <color rgba="1 0 0 1"/>
  </material>
  <link name="world"/>
  <link name="base_link">
    <inertial>
      <origin rpy="0 0 0" xyz="0 0 0"/>
      <mass value="1.0"/>
      <inertia ixx="1.0" ixy="0.0" ixz="0.0" iyy="1.0" iyz="0.0" izz="1.0"/>
    </inertial>
    <visual>
      <origin rpy="0 0 0" xyz="-0.5 -0.5 0"/>
      <geometry>
        <mesh filename="file:///home/albert/umov_ws/install/description/share/description/meshes/basement.STL" scale="0.01 0.01 0.01"/>
      </geometry>
      <material name="blue"/>
    </visual>
    <collision>
      <origin rpy="0 0 0" xyz="-0.5 -0.5 0"/>
      <geometry>
        <mesh filename="file:///home/albert/umov_ws/install/description/share/description/meshes/basement.STL" scale="0.01 0.01 0.01"/>
      </geometry>
    </collision>
  </link>
  <link name="base_plate">
    <inertial>
      <origin rpy="0 0 0" xyz="0 0 0"/>
      <mass value="0.1"/>
      <inertia ixx="1.0" ixy="0.0" ixz="0.0" iyy="1.0" iyz="0.0" izz="1.0"/>
    </inertial>
    <visual>
      <origin rpy="0 0 0" xyz="-0.39 -0.39 -0.56"/>
      <geometry>
        <mesh filename="file:///home/albert/umov_ws/install/description/share/description/meshes/base_plate.STL" scale="0.01 0.01 0.01"/>
      </geometry>
      <material name="red"/>
    </visual>
    <collision>
      <origin rpy="0 0 0" xyz="-0.39 -0.39 -0.56"/>
      <geometry>
        <mesh filename="file:///home/albert/umov_ws/install/description/share/description/meshes/base_plate.STL" scale="0.01 0.01 0.01"/>
      </geometry>
    </collision>
  </link>
  <!-- <link name="rgb_camera">
        <xacro:default_inertia mass="0.001"/>
        <visual>
            <origin rpy="-1.57 0 -1.57" xyz="-0.1 0.125 0.15"/>
            <geometry>
                <mesh filename="file://$(find description)/meshes/pi_camera.STL" scale="${scale}"/>
            </geometry>
        </visual>
        <collision>
            <origin rpy="-1.57 0 -1.57" xyz="-0.1 0.125 0.15"/>
            <geometry>
                <mesh filename="file://$(find description)/meshes/pi_camera.STL" scale="${scale}"/>
            </geometry> 
        </collision>
    </link> -->
  <link name="forward_drive_arm">
    <inertial>
      <origin rpy="0 0 0" xyz="0 0 0"/>
      <mass value="0.1"/>
      <inertia ixx="1.0" ixy="0.0" ixz="0.0" iyy="1.0" iyz="0.0" izz="1.0"/>
    </inertial>
    <visual>
      <origin rpy="0 -1.570796326795 1.570796326795" xyz="0.19 0.06 -0.08"/>
      <geometry>
        <mesh filename="file:///home/albert/umov_ws/install/description/share/description/meshes/forward_drive_arm.STL" scale="0.01 0.01 0.01"/>
      </geometry>
      <material name="purple"/>
    </visual>
    <collision>
      <origin rpy="0 -1.570796326795 1.570796326795" xyz="0.19 0.06 -0.08"/>
      <geometry>
        <mesh filename="file:///home/albert/umov_ws/install/description/share/description/meshes/forward_drive_arm.STL" scale="0.01 0.01 0.01"/>
      </geometry>
    </collision>
  </link>
  <link name="horizontal_arm">
    <inertial>
      <origin rpy="0 0 0" xyz="0 0 0"/>
      <mass value="0.1"/>
      <inertia ixx="1.0" ixy="0.0" ixz="0.0" iyy="1.0" iyz="0.0" izz="1.0"/>
    </inertial>
    <visual>
      <origin rpy="1.570796326795 0 1.570796326795" xyz="-0.03 -0.4 -0.06"/>
      <geometry>
        <mesh filename="file:///home/albert/umov_ws/install/description/share/description/meshes/horizontal_arm.STL" scale="0.01 0.01 0.01"/>
      </geometry>
      <material name="turquoise"/>
    </visual>
    <collision>
      <origin rpy="1.570796326795 0 1.570796326795" xyz="-0.03 -0.4 -0.06"/>
      <geometry>
        <mesh filename="file:///home/albert/umov_ws/install/description/share/description/meshes/horizontal_arm.STL" scale="0.01 0.01 0.01"/>
      </geometry>
    </collision>
  </link>
  <link name="claw_support">
    <inertial>
      <origin rpy="0 0 0" xyz="0 0 0"/>
      <mass value="0.05"/>
      <inertia ixx="1.0" ixy="0.0" ixz="0.0" iyy="1.0" iyz="0.0" izz="1.0"/>
    </inertial>
    <visual>
      <origin rpy="0 0 1.570796326795" xyz="0 -0.05 -0.15"/>
      <geometry>
        <mesh filename="file:///home/albert/umov_ws/install/description/share/description/meshes/claw_support.STL" scale="0.01 0.01 0.01"/>
      </geometry>
      <material name="yellow"/>
    </visual>
    <collision>
      <origin rpy="0 0 1.570796326795" xyz="0 -0.05 -0.15"/>
      <geometry>
        <mesh filename="file:///home/albert/umov_ws/install/description/share/description/meshes/claw_support.STL" scale="0.01 0.01 0.01"/>
      </geometry>
    </collision>
  </link>
  <link name="gripper_right">
    <inertial>
      <origin rpy="0 0 0" xyz="0 0 0"/>
      <mass value="0.01"/>
      <inertia ixx="1.0" ixy="0.0" ixz="0.0" iyy="1.0" iyz="0.0" izz="1.0"/>
    </inertial>
    <visual>
      <origin rpy="0 0 -1.570796326795" xyz="-0.1 0.50 -0.1"/>
      <geometry>
        <mesh filename="file:///home/albert/umov_ws/install/description/share/description/meshes/right_finger.STL" scale="0.01 0.01 0.01"/>
      </geometry>
      <material name="orange"/>
    </visual>
    <collision>
      <origin rpy="0 0 -1.570796326795" xyz="-0.1 0.50 -0.1"/>
      <geometry>
        <mesh filename="file:///home/albert/umov_ws/install/description/share/description/meshes/right_finger.STL" scale="0.01 0.01 0.01"/>
      </geometry>
    </collision>
  </link>
  <link name="gripper_left">
    <inertial>
      <origin rpy="0 0 0" xyz="0 0 0"/>
      <mass value="0.01"/>
      <inertia ixx="1.0" ixy="0.0" ixz="0.0" iyy="1.0" iyz="0.0" izz="1.0"/>
    </inertial>
    <visual>
      <origin rpy="0 0 -1.570796326795" xyz="-0.04 0.50 -0.1"/>
      <geometry>
        <mesh filename="file:///home/albert/umov_ws/install/description/share/description/meshes/left_finger.STL" scale="0.01 0.01 0.01"/>
      </geometry>
      <material name="orange"/>
    </visual>
    <collision>
      <origin rpy="0 0 -1.570796326795" xyz="-0.04 0.50 -0.1"/>
      <geometry>
        <mesh filename="file:///home/albert/umov_ws/install/description/share/description/meshes/left_finger.STL" scale="0.01 0.01 0.01"/>
      </geometry>
    </collision>
  </link>
  <joint name="virtual_joint" type="fixed">
    <parent link="world"/>
    <child link="base_link"/>
    <origin rpy="0 0 0" xyz="0 0 0"/>
  </joint>
  <joint name="joint_1" type="revolute">
    <parent link="base_link"/>
    <child link="base_plate"/>
    <origin xyz="0 0 0.307"/>
    <axis xyz="0 0 1"/>
    <limit effort="30.0" lower="-1.570796326795" upper="1.570796326795" velocity="10.0"/>
  </joint>
  <!-- <joint name="rgb_camera_link" type="fixed">
        <parent link="base_link"/>
        <child link="rgb_camera"/>
        <origin xyz="0 0.45 0.2" rpy="0 -0.1 1.57"/>
        </joint> -->
  <joint name="joint_2" type="revolute">
    <parent link="base_plate"/>
    <child link="forward_drive_arm"/>
    <origin xyz="-0.02 0 0.35"/>
    <axis xyz="1 0 0"/>
    <limit effort="30.0" lower="-1.570796326795" upper="1.570796326795" velocity="10.0"/>
  </joint>
  <joint name="joint_3" type="revolute">
    <parent link="forward_drive_arm"/>
    <child link="horizontal_arm"/>
    <origin xyz="0 0 0.8"/>
    <axis xyz="1 0 0"/>
    <limit effort="30.0" lower="-1.570796326795" upper="1.570796326795" velocity="10.0"/>
  </joint>
  <joint name="joint_4" type="revolute">
    <parent link="horizontal_arm"/>
    <child link="claw_support"/>
    <origin xyz="0 0.82 0"/>
    <axis xyz="1 0 0"/>
    <limit effort="30.0" lower="-1.570796326795" upper="1.570796326795" velocity="10.0"/>
  </joint>
  <joint name="joint_5" type="revolute">
    <parent link="claw_support"/>
    <child link="gripper_right"/>
    <origin xyz="-0.04 0.13 -0.1"/>
    <axis xyz="0 0 1"/>
    <limit effort="30.0" lower="-1.570796326795" upper="0.0" velocity="10.0"/>
  </joint>
  <joint name="joint_6" type="revolute">
    <parent link="claw_support"/>
    <child link="gripper_left"/>
    <origin xyz="-0.22 0.13 -0.1"/>
    <axis xyz="0 0 1"/>
    <limit effort="30.0" lower="0.0" upper="1.570796326795" velocity="10.0"/>
    <mimic joint="joint_5" multiplier="-1"/>
  </joint>
  <!-- <gazebo reference="rgb_camera">
        <sensor type="camera" name="camera_1"> 
            <always_on>true</always_on>
            <update_rate>1</update_rate>

            <camera name="rgb_camera">
            <horizontal_fov>1.15</horizontal_fov>
            <vertical_fov>0.71</vertical_fov>
            <image>
                <width>2304</width>
                <height>1296</height>
                <format>R8G8B8</format>
            </image>
            <clip>
                <near>0.02</near>
                <far>300</far>
            </clip>
            <noise>
                <type>gaussian</type>
                <mean>0.0</mean>
                <stddev>0.007</stddev> 
            </noise>

            </camera>

            <plugin name="camera_controller" filename="libgazebo_ros_camera.so">
                <ros>
                    <remapping>image_raw:=image_raw</remapping>
                    <remapping>camera_info:=camera_info</remapping>
                </ros>

                <camera_name>rgb_camera</camera_name>

                <frame_name>rgb_camera</frame_name>

                <hack_baseline>0.07</hack_baseline>

                <distortion>
                    <k1>0.1</k1>
                    <k2>0.2</k2>
                    <k3>0.3</k3>
                    <p1>0.4</p1>
                    <p2>0.5</p2>
                    <center>0.5 0.5</center>
                </distortion> 

            </plugin> 
        </sensor>
    </gazebo> -->
  <transmission name="transmission_1">
    <plugin>transmission_interface/SimpleTransmission</plugin>
    <actuator name="motor_1" role="actuator1"/>
    <joint name="joint_1" role="joint1">
      <mechanical_reduction>1.0</mechanical_reduction>
    </joint>
  </transmission>
  <transmission name="transmission_2">
    <plugin>transmission_interface/SimpleTransmission</plugin>
    <actuator name="motor_2" role="actuator1"/>
    <joint name="joint_2" role="joint1">
      <mechanical_reduction>1.0</mechanical_reduction>
    </joint>
  </transmission>
  <transmission name="transmission_3">
    <plugin>transmission_interface/SimpleTransmission</plugin>
    <actuator name="motor_3" role="actuator1"/>
    <joint name="joint_3" role="joint1">
      <mechanical_reduction>1.0</mechanical_reduction>
    </joint>
  </transmission>
  <transmission name="transmission_4">
    <plugin>transmission_interface/SimpleTransmission</plugin>
    <actuator name="motor_4" role="actuator1"/>
    <joint name="joint_4" role="joint1">
      <mechanical_reduction>1.0</mechanical_reduction>
    </joint>
  </transmission>
  <transmission name="transmission_5">
    <plugin>transmission_interface/SimpleTransmission</plugin>
    <actuator name="motor_5" role="actuator1"/>
    <joint name="joint_5" role="joint1">
      <mechanical_reduction>1.0</mechanical_reduction>
    </joint>
  </transmission>
</robot>
